<robot
  name="bionicarm" xmlns:xacro="http://www.ros.org/wiki/xacro">
  
  <xacro:include filename="$(find bionicarm_description)/urdf/materials.xacro" />
  
  <xacro:include filename="$(find bionicarm_description)/urdf/bionicarm_robot.gazebo" />
  
  <xacro:include filename="$(find bionicarm_description)/urdf/bionicarm_transmission.xacro" />
  
  <xacro:property name="PI" value="3.1415926535897931"/>
  
  <link name="world"/>
  
  <joint name="world_base" type="fixed">
    <origin
      xyz="0 0 0"
      rpy="0 0 0" />
    <parent
      link="world" />
    <child
      link="body" />
  </joint>

  <link
    name="body">
    <inertial>
      <origin
        xyz="-0.00033894 0.13426 0.00086461"
        rpy="0 0 0" />
      <mass
        value="112.17" />
      <inertia
        ixx="16.8"
        ixy="0.036733"
        ixz="0.0052002"
        iyy="16.713"
        iyz="-0.083938"
        izz="16.796" />
    </inertial>
    <visual>
      <origin
        xyz="0 0 0"
        rpy="0 0 0" />
      <geometry>
        <mesh
          filename="package://bionicarm_description/meshes/body.STL" />
      </geometry>
      <material
        name="">
        <color
          rgba="0.79216 0.81961 0.93333 1" />
      </material>
    </visual>
    <collision>
      <origin
        xyz="0 0 0"
        rpy="0 0 0" />
      <geometry>
        <mesh
          filename="package://bionicarm_description/meshes/body.STL" />
      </geometry>
    </collision>
  </link>
  <link
    name="j1shoulderpitch">
    <inertial>
      <origin
        xyz="-0.00025394 -0.040554 2.291E-05"
        rpy="0 0 0" />
      <mass
        value="0.16692" />
      <inertia
        ixx="0.00013545"
        ixy="-3.6482E-07"
        ixz="-5.6402E-09"
        iyy="8.9147E-05"
        iyz="2.5741E-07"
        izz="0.00014534" />
    </inertial>
    <visual>
      <origin
        xyz="0 0 0"
        rpy="0 0 0" />
      <geometry>
        <mesh
          filename="package://bionicarm_description/meshes/j1shoulderpitch.STL" />
      </geometry>
      <material
        name="">
        <color
          rgba="0.79216 0.81961 0.93333 1" />
      </material>
    </visual>
    <collision>
      <origin
        xyz="0 0 0"
        rpy="0 0 0" />
      <geometry>
        <mesh
          filename="package://bionicarm_description/meshes/j1shoulderpitch.STL" />
      </geometry>
    </collision>
  </link>
  <joint
    name="joint1"
    type="revolute">
    <origin
      xyz="-0.055 -0.2 1"
      rpy="-6.123E-17 0 0" />
    <parent
      link="body" />
    <child
      link="j1shoulderpitch" />
    <axis
      xyz="0 1 0" />
    <limit
      lower="-3.14"
      upper="3.14"
      effort="120"
      velocity="1.57" />
  </joint>
  <link
    name="j2shoulderroll">
    <inertial>
      <origin
        xyz="-0.0053448 -9.9715E-06 -0.095581"
        rpy="0 0 0" />
      <mass
        value="0.38076" />
      <inertia
        ixx="0.0011838"
        ixy="1.4847E-08"
        ixz="0.00010651"
        iyy="0.0013307"
        iyz="1.4605E-06"
        izz="0.00035539" />
    </inertial>
    <visual>
      <origin
        xyz="0 0 0"
        rpy="0 0 0" />
      <geometry>
        <mesh
          filename="package://bionicarm_description/meshes/j2shoulderroll.STL" />
      </geometry>
      <material
        name="">
        <color
          rgba="0.79216 0.81961 0.93333 1" />
      </material>
    </visual>
    <collision>
      <origin
        xyz="0 0 0"
        rpy="0 0 0" />
      <geometry>
        <mesh
          filename="package://bionicarm_description/meshes/j2shoulderroll.STL" />
      </geometry>
    </collision>
  </link>
  <joint
    name="joint2"
    type="revolute">
    <origin
      xyz="0 -0.05205 0"
      rpy="0 0 0" />
    <parent
      link="j1shoulderpitch" />
    <child
      link="j2shoulderroll" />
    <axis
      xyz="1 0 0" />
    <limit
      lower="-3.14"
      upper="3.14"
      effort="120"
      velocity="1.57" />
  </joint>
  <link
    name="j3shoulderyaw">
    <inertial>
      <origin
        xyz="0.00080625 -0.0025762 -0.11928"
        rpy="0 0 0" />
      <mass
        value="0.32461" />
      <inertia
        ixx="0.0023925"
        ixy="5.7664E-06"
        ixz="5.563E-06"
        iyy="0.0023592"
        iyz="-9.2987E-06"
        izz="0.00031641" />
    </inertial>
    <visual>
      <origin
        xyz="0 0 0"
        rpy="0 0 0" />
      <geometry>
        <mesh
          filename="package://bionicarm_description/meshes/j3shoulderyaw.STL" />
      </geometry>
      <material
        name="">
        <color
          rgba="0.79216 0.81961 0.93333 1" />
      </material>
    </visual>
    <collision>
      <origin
        xyz="0 0 0"
        rpy="0 0 0" />
      <geometry>
        <mesh
          filename="package://bionicarm_description/meshes/j3shoulderyaw.STL" />
      </geometry>
    </collision>
  </link>
  <joint
    name="joint3"
    type="revolute">
    <origin
      xyz="0 0 -0.1862"
      rpy="0 0 -0.17453" />
    <parent
      link="j2shoulderroll" />
    <child
      link="j3shoulderyaw" />
    <axis
      xyz="0 0 1" />
    <limit
      lower="-3.14"
      upper="3.14"
      effort="120"
      velocity="1.57" />
  </joint>
  <link
    name="j4elbowpitch">
    <inertial>
      <origin
        xyz="0.012269 -0.018945 -0.02502"
        rpy="0 0 0" />
      <mass
        value="0.082897" />
      <inertia
        ixx="3.8752E-05"
        ixy="-3.6624E-06"
        ixz="1.9961E-06"
        iyy="5.0228E-05"
        iyz="-9.6582E-06"
        izz="5.8994E-05" />
    </inertial>
    <visual>
      <origin
        xyz="0 0 0"
        rpy="0 0 0" />
      <geometry>
        <mesh
          filename="package://bionicarm_description/meshes/j4elbowpitch.STL" />
      </geometry>
      <material
        name="">
        <color
          rgba="0.79216 0.81961 0.93333 1" />
      </material>
    </visual>
    <collision>
      <origin
        xyz="0 0 0"
        rpy="0 0 0" />
      <geometry>
        <mesh
          filename="package://bionicarm_description/meshes/j4elbowpitch.STL" />
      </geometry>
    </collision>
  </link>
  <joint
    name="joint4"
    type="revolute">
    <origin
      xyz="0 0 -0.278"
      rpy="0 0 0.17453" />
    <parent
      link="j3shoulderyaw" />
    <child
      link="j4elbowpitch" />
    <axis
      xyz="0 1 0" />
    <limit
      lower="-3.14"
      upper="3.14"
      effort="120"
      velocity="1.57" />
  </joint>
  <link
    name="j5elbowroll">
    <inertial>
      <origin
        xyz="0.070311 0.00040826 0.00036134"
        rpy="0 0 0" />
      <mass
        value="0.1042" />
      <inertia
        ixx="8.7438E-05"
        ixy="2.4472E-07"
        ixz="-1.26E-07"
        iyy="0.0004119"
        iyz="1.8938E-05"
        izz="0.00041088" />
    </inertial>
    <visual>
      <origin
        xyz="0 0 0"
        rpy="0 0 0" />
      <geometry>
        <mesh
          filename="package://bionicarm_description/meshes/j5elbowroll.STL" />
      </geometry>
      <material
        name="">
        <color
          rgba="0.79216 0.81961 0.93333 1" />
      </material>
    </visual>
    <collision>
      <origin
        xyz="0 0 0"
        rpy="0 0 0" />
      <geometry>
        <mesh
          filename="package://bionicarm_description/meshes/j5elbowroll.STL" />
      </geometry>
    </collision>
  </link>
  <joint
    name="joint5"
    type="revolute">
    <origin
      xyz="0.048605 0.0095 -0.029355"
      rpy="0 0 0" />
    <parent
      link="j4elbowpitch" />
    <child
      link="j5elbowroll" />
    <axis
      xyz="1 0 0" />
    <limit
      lower="-3.14"
      upper="3.14"
      effort="120"
      velocity="1.57" />
  </joint>
  <link
    name="wristhand">
    <inertial>
      <origin
        xyz="0.081776 0.0040028 0.0096205"
        rpy="0 0 0" />
      <mass
        value="0.18834" />
      <inertia
        ixx="0.0002296"
        ixy="9.0797E-06"
        ixz="-2.7607E-05"
        iyy="0.00078594"
        iyz="-5.4756E-05"
        izz="0.00070395" />
    </inertial>
    <visual>
      <origin
        xyz="0 0 0"
        rpy="0 0 0" />
      <geometry>
        <mesh
          filename="package://bionicarm_description/meshes/wristhand.STL" />
      </geometry>
      <material
        name="">
        <color
          rgba="0.79216 0.81961 0.93333 1" />
      </material>
    </visual>
    <collision>
      <origin
        xyz="0 0 0"
        rpy="0 0 0" />
      <geometry>
        <mesh
          filename="package://bionicarm_description/meshes/wristhand.STL" />
      </geometry>
    </collision>
  </link>
  <joint
    name="wristfixed"
    type="fixed">
    <origin
      xyz="0.17975 0 0"
      rpy="1.1102E-14 0 0" />
    <parent
      link="j5elbowroll" />
    <child
      link="wristhand" />
    <axis
      xyz="0 0 0" />
  </joint>
  
  <link name="bionicarm_end_link"/>
  
  <joint name="bionicarm_end_joint" type="fixed">
    <origin
      xyz="0 -0.091 0"
      rpy="${PI/2} ${-PI/2} 0" />
    <parent
      link="wristfixed" />
    <child
      link="bionicarm_end_link" />
  </joint>
  
  <link name="bionicarm_dummy_gripper"/>
  
  <joint name="bionicarm_dummy_joint" type="fixed">
    <origin
      xyz="0 -0.111 0"
      rpy="${PI/2} ${-PI/2} 0" />
    <parent
      link="wristfixed" />
    <child
      link="bionicarm_dummy_gripper" />
  </joint>
  
</robot>
